**异常处理：** 熟悉Java的异常体系，了解如何使用try-catch块来捕获和处理异常。

- Java的异常体系是一种用于处理程序运行时错误和异常情况的机制。在Java中，异常是派生于 `java.lang.Exception` 类的对象，用于表示程序运行过程中出现的异常情况。异常分为两种主要类型：受检异常（Checked Exceptions）和非受检异常（Unchecked Exceptions，也称为运行时异常）。

  **受检异常（Checked Exceptions）：** 这些异常在编译时会被检查，如果不处理，程序将无法编译通过。常见的受检异常包括 `IOException`、`SQLException` 等。处理受检异常的一种方式是使用 `try-catch` 块捕获异常。

  **非受检异常（Unchecked Exceptions，运行时异常）：** 这些异常不需要在代码中显式地进行处理。常见的非受检异常包括 `NullPointerException`、`ArithmeticException`、`ArrayIndexOutOfBoundsException` 等。这些异常通常表示程序错误或逻辑问题，应该在程序中修复。

  以下是如何使用 `try-catch` 块来捕获和处理异常的示例：

  ```java
  public class ExceptionHandling {
      public static void main(String[] args) {
          try {
              int result = divide(10, 0); // 调用可能引发异常的方法
              System.out.println("Result: " + result);
          } catch (ArithmeticException e) {
              System.out.println("An error occurred: " + e.getMessage());
          } finally {
              System.out.println("Finally block executed");
          }
  
          System.out.println("Program continues after exception handling");
      }
  
      // 可能引发异常的方法
      public static int divide(int a, int b) {
          return a / b;
      }
  }
  ```

  在上述示例中：

  - 我们调用了 `divide` 方法，该方法可能引发 `ArithmeticException`（除以零）。
  - 我们使用 `try-catch` 块来捕获可能引发的异常。如果异常发生，catch 块中的代码将被执行。
  - `catch` 块中的异常类型 `ArithmeticException` 对应了我们可能捕获的异常类型。可以根据情况添加多个 `catch` 块来处理不同类型的异常。
  - `finally` 块中的代码无论异常是否发生都会被执行，通常用于资源释放等操作。
  - 程序在异常处理后继续执行，而不会中断。

  通过使用 `try-catch` 块，你可以在程序中捕获和处理异常，以使程序更加健壮并避免未处理的异常导致程序中断。