使用 try-except 块来处理异常，以及如何自定义异常类。

- 

在 Python 中，可以使用 try-except 块来处理异常，以捕获并处理可能出现的错误情况。同时，你还可以自定义异常类，以便更好地表示和处理特定类型的错误。

**使用 try-except 块处理异常：**
```python
try:
    # 可能引发异常的代码块
    result = 10 / 0  # 除零异常
except ZeroDivisionError:
    print("除零异常发生")
```

在上面的例子中，try 块中的代码计算了一个除零操作，这会引发 `ZeroDivisionError` 异常。在 except 块中，我们捕获了这个特定类型的异常并打印了一条错误消息。

**自定义异常类：**
```python
class MyCustomError(Exception):
    def __init__(self, message):
        self.message = message

try:
    age = int(input("请输入年龄："))
    if age < 0:
        raise MyCustomError("年龄不能为负数")
except MyCustomError as e:
    print("发生自定义异常：", e.message)
except ValueError:
    print("请输入有效的数字")
```

在这个例子中，我们定义了一个自定义异常类 `MyCustomError`，它继承自内置的 `Exception` 类。我们通过 `raise` 语句抛出自定义异常，然后在 except 块中捕获并处理它。

使用 try-except 块和自定义异常类可以使代码更具健壮性，能够在出现问题时提供更详细和有意义的错误信息，从而更好地进行异常处理和调试。